[2023-08-17T15:00:56.385-0600] {taskinstance.py:1103} INFO - Dependencies all met for dep_context=non-requeueable deps ti=<TaskInstance: Respaldar_Base_De_Datos.mover_respaldo scheduled__2023-08-16T06:00:00+00:00 [queued]>
[2023-08-17T15:00:56.400-0600] {taskinstance.py:1103} INFO - Dependencies all met for dep_context=requeueable deps ti=<TaskInstance: Respaldar_Base_De_Datos.mover_respaldo scheduled__2023-08-16T06:00:00+00:00 [queued]>
[2023-08-17T15:00:56.400-0600] {taskinstance.py:1308} INFO - Starting attempt 1 of 2
[2023-08-17T15:00:56.427-0600] {taskinstance.py:1327} INFO - Executing <Task(SSHOperator): mover_respaldo> on 2023-08-16 06:00:00+00:00
[2023-08-17T15:00:56.432-0600] {standard_task_runner.py:57} INFO - Started process 1539 to run task
[2023-08-17T15:00:56.437-0600] {standard_task_runner.py:84} INFO - Running: ['airflow', 'tasks', 'run', 'Respaldar_Base_De_Datos', 'mover_respaldo', 'scheduled__2023-08-16T06:00:00+00:00', '--job-id', '11', '--raw', '--subdir', 'DAGS_FOLDER/crear_respaldo_base_de_datos.py', '--cfg-path', '/tmp/tmp300tm5zh']
[2023-08-17T15:00:56.440-0600] {standard_task_runner.py:85} INFO - Job 11: Subtask mover_respaldo
[2023-08-17T15:00:56.507-0600] {task_command.py:410} INFO - Running <TaskInstance: Respaldar_Base_De_Datos.mover_respaldo scheduled__2023-08-16T06:00:00+00:00 [running]> on host f001d94713ae
[2023-08-17T15:00:56.652-0600] {taskinstance.py:1547} INFO - Exporting env vars: AIRFLOW_CTX_DAG_OWNER='airflow' AIRFLOW_CTX_DAG_ID='Respaldar_Base_De_Datos' AIRFLOW_CTX_TASK_ID='mover_respaldo' AIRFLOW_CTX_EXECUTION_DATE='2023-08-16T06:00:00+00:00' AIRFLOW_CTX_TRY_NUMBER='1' AIRFLOW_CTX_DAG_RUN_ID='scheduled__2023-08-16T06:00:00+00:00'
[2023-08-17T15:00:56.653-0600] {ssh.py:135} INFO - Creating ssh_client
[2023-08-17T15:00:56.754-0600] {ssh.py:112} INFO - ssh_hook is not provided or invalid. Trying ssh_conn_id to create SSHHook.
[2023-08-17T15:00:56.765-0600] {base.py:73} INFO - Using connection ID 'gabo_ssh' for task execution.
[2023-08-17T15:00:56.765-0600] {ssh.py:299} WARNING - No Host Key Verification. This won't protect against Man-In-The-Middle attacks
[2023-08-17T15:00:56.793-0600] {transport.py:1873} INFO - Connected (version 2.0, client OpenSSH_9.2p1)
[2023-08-17T15:00:56.944-0600] {transport.py:1873} INFO - Authentication (password) successful!
[2023-08-17T15:00:56.945-0600] {ssh.py:476} INFO - Running command: mv /tmp/2023-08-16_database_backup_file.tar.gz ~/Dropbox/Inversiones_Garotas_Bonitas/GABO/respaldos/base_de_datos
[2023-08-17T15:00:57.093-0600] {ssh.py:527} WARNING - mv: no se puede mover '/tmp/2023-08-16_database_backup_file.tar.gz' a '/home/ambiente_admin/Dropbox/Inversiones_Garotas_Bonitas/GABO/respaldos/base_de_datos'
[2023-08-17T15:00:57.093-0600] {ssh.py:527} WARNING - : No existe el fichero o el directorio
[2023-08-17T15:00:57.120-0600] {taskinstance.py:1824} ERROR - Task failed with exception
Traceback (most recent call last):
  File "/home/airflow/.local/lib/python3.7/site-packages/airflow/providers/ssh/operators/ssh.py", line 173, in execute
    result = self.run_ssh_client_command(ssh_client, self.command, context=context)
  File "/home/airflow/.local/lib/python3.7/site-packages/airflow/providers/ssh/operators/ssh.py", line 161, in run_ssh_client_command
    self.raise_for_status(exit_status, agg_stderr, context=context)
  File "/home/airflow/.local/lib/python3.7/site-packages/airflow/providers/ssh/operators/ssh.py", line 154, in raise_for_status
    raise AirflowException(f"SSH operator error: exit status = {exit_status}")
airflow.exceptions.AirflowException: SSH operator error: exit status = 1
[2023-08-17T15:00:57.126-0600] {taskinstance.py:1350} INFO - Marking task as UP_FOR_RETRY. dag_id=Respaldar_Base_De_Datos, task_id=mover_respaldo, execution_date=20230816T060000, start_date=20230817T210056, end_date=20230817T210057
[2023-08-17T15:00:57.141-0600] {standard_task_runner.py:109} ERROR - Failed to execute job 11 for task mover_respaldo (SSH operator error: exit status = 1; 1539)
[2023-08-17T15:00:57.170-0600] {local_task_job_runner.py:225} INFO - Task exited with return code 1
[2023-08-17T15:00:57.215-0600] {taskinstance.py:2651} INFO - 0 downstream tasks scheduled from follow-on schedule check
