[2023-08-17T15:04:56.757-0600] {taskinstance.py:1103} INFO - Dependencies all met for dep_context=non-requeueable deps ti=<TaskInstance: Respaldar_Documentos_Electronicos.sincronizar_archivos manual__2023-08-17T21:04:54.773641+00:00 [queued]>
[2023-08-17T15:04:56.778-0600] {taskinstance.py:1103} INFO - Dependencies all met for dep_context=requeueable deps ti=<TaskInstance: Respaldar_Documentos_Electronicos.sincronizar_archivos manual__2023-08-17T21:04:54.773641+00:00 [queued]>
[2023-08-17T15:04:56.778-0600] {taskinstance.py:1308} INFO - Starting attempt 1 of 2
[2023-08-17T15:04:56.807-0600] {taskinstance.py:1327} INFO - Executing <Task(SSHOperator): sincronizar_archivos> on 2023-08-17 21:04:54.773641+00:00
[2023-08-17T15:04:56.815-0600] {standard_task_runner.py:57} INFO - Started process 1811 to run task
[2023-08-17T15:04:56.820-0600] {standard_task_runner.py:84} INFO - Running: ['airflow', 'tasks', 'run', 'Respaldar_Documentos_Electronicos', 'sincronizar_archivos', 'manual__2023-08-17T21:04:54.773641+00:00', '--job-id', '15', '--raw', '--subdir', 'DAGS_FOLDER/respaldar_documentos_electronicos.py', '--cfg-path', '/tmp/tmprk09ozhp']
[2023-08-17T15:04:56.823-0600] {standard_task_runner.py:85} INFO - Job 15: Subtask sincronizar_archivos
[2023-08-17T15:04:56.885-0600] {task_command.py:410} INFO - Running <TaskInstance: Respaldar_Documentos_Electronicos.sincronizar_archivos manual__2023-08-17T21:04:54.773641+00:00 [running]> on host f001d94713ae
[2023-08-17T15:04:57.038-0600] {taskinstance.py:1547} INFO - Exporting env vars: AIRFLOW_CTX_DAG_OWNER='airflow' AIRFLOW_CTX_DAG_ID='Respaldar_Documentos_Electronicos' AIRFLOW_CTX_TASK_ID='sincronizar_archivos' AIRFLOW_CTX_EXECUTION_DATE='2023-08-17T21:04:54.773641+00:00' AIRFLOW_CTX_TRY_NUMBER='1' AIRFLOW_CTX_DAG_RUN_ID='manual__2023-08-17T21:04:54.773641+00:00'
[2023-08-17T15:04:57.038-0600] {ssh.py:135} INFO - Creating ssh_client
[2023-08-17T15:04:57.090-0600] {ssh.py:112} INFO - ssh_hook is not provided or invalid. Trying ssh_conn_id to create SSHHook.
[2023-08-17T15:04:57.102-0600] {base.py:73} INFO - Using connection ID 'gabo_ssh' for task execution.
[2023-08-17T15:04:57.103-0600] {ssh.py:299} WARNING - No Host Key Verification. This won't protect against Man-In-The-Middle attacks
[2023-08-17T15:04:57.123-0600] {transport.py:1873} INFO - Connected (version 2.0, client OpenSSH_9.2p1)
[2023-08-17T15:04:57.276-0600] {transport.py:1873} INFO - Authentication (password) successful!
[2023-08-17T15:04:57.277-0600] {ssh.py:476} INFO - Running command: rsync -a /var/www/gabos/application/third_party/ ~/Dropbox/Inversiones_Garotas_Bonitas/GABO/respaldos/documentos_electronicos
[2023-08-17T15:04:57.476-0600] {ssh.py:527} WARNING - rsync: [sender] send_files failed to open "/var/www/gabos/application/third_party/certificados/1ae00a0691a2e7ccf48ba9c910b55a3a.p12": Permission denied (13)
[2023-08-17T15:04:57.476-0600] {ssh.py:527} WARNING - rsync: [sender] send_files failed to open "/var/www/gabos/application/third_party/factura_electronica/2023_08_17/50617082300310135078500100001040000086668181029965.pdf": Permission denied (13)
[2023-08-17T15:04:57.476-0600] {ssh.py:527} WARNING - rsync: [sender] send_files failed to open "/var/www/gabos/application/third_party/factura_electronica/2023_08_17/50617082300310135078500100001040000086668181029965.xml": Permission denied (13)
[2023-08-17T15:04:57.476-0600] {ssh.py:527} WARNING - rsync: [sender] send_files failed to open "/var/www/gabos/application/third_party/factura_electronica/2023_08_17/50617082300310135078500100001040000086668281029965.xml": Permission denied (13)
[2023-08-17T15:04:57.476-0600] {ssh.py:527} WARNING - rsync: [sender] send_files failed to open "/var/www/gabos/application/third_party/factura_electronica/2023_08_17/50617082300310135078500100001040000086669159993989.pdf": Permission denied (13)
[2023-08-17T15:04:57.477-0600] {ssh.py:527} WARNING - rsync: [sender] send_files failed to open "/var/www/gabos/application/third_party/factura_electronica/2023_08_17/50617082300310135078500100001040000086669159993989.xml": Permission denied (13)
[2023-08-17T15:04:57.477-0600] {ssh.py:527} WARNING - rsync: [sender] send_files failed to open "/var/www/gabos/application/third_party/factura_electronica/2023_08_17/50617082300310135078500100001040000086669259993989.xml": Permission denied (13)
[2023-08-17T15:04:57.477-0600] {ssh.py:527} WARNING - rsync: [sender] send_files failed to open "/var/www/gabos/application/third_party/factura_electronica/2023_08_17/50617082300310135078500100001040000086670178405024.pdf": Permission denied (13)
[2023-08-17T15:04:57.478-0600] {ssh.py:527} WARNING - rsync: [sender] send_files failed to open "/var/www/gabos/application/third_party/factura_electronica/2023_08_17/50617082300310135078500100001040000086670178405024.xml": Permission denied (13)
[2023-08-17T15:04:57.478-0600] {ssh.py:527} WARNING - rsync: [sender] send_files failed to open "/var/www/gabos/application/third_party/factura_electronica/2023_08_17/50617082300310135078500100001040000086670278405024.xml": Permission denied (13)
[2023-08-17T15:04:57.622-0600] {ssh.py:527} WARNING - rsync error: some files/attrs were not transferred (see previous errors) (code 23) at main.c(1338) [sender=3.2.7]
[2023-08-17T15:04:57.652-0600] {taskinstance.py:1824} ERROR - Task failed with exception
Traceback (most recent call last):
  File "/home/airflow/.local/lib/python3.7/site-packages/airflow/providers/ssh/operators/ssh.py", line 173, in execute
    result = self.run_ssh_client_command(ssh_client, self.command, context=context)
  File "/home/airflow/.local/lib/python3.7/site-packages/airflow/providers/ssh/operators/ssh.py", line 161, in run_ssh_client_command
    self.raise_for_status(exit_status, agg_stderr, context=context)
  File "/home/airflow/.local/lib/python3.7/site-packages/airflow/providers/ssh/operators/ssh.py", line 154, in raise_for_status
    raise AirflowException(f"SSH operator error: exit status = {exit_status}")
airflow.exceptions.AirflowException: SSH operator error: exit status = 23
[2023-08-17T15:04:57.658-0600] {taskinstance.py:1350} INFO - Marking task as UP_FOR_RETRY. dag_id=Respaldar_Documentos_Electronicos, task_id=sincronizar_archivos, execution_date=20230817T210454, start_date=20230817T210456, end_date=20230817T210457
[2023-08-17T15:04:57.678-0600] {standard_task_runner.py:109} ERROR - Failed to execute job 15 for task sincronizar_archivos (SSH operator error: exit status = 23; 1811)
[2023-08-17T15:04:57.693-0600] {local_task_job_runner.py:225} INFO - Task exited with return code 1
[2023-08-17T15:04:57.721-0600] {taskinstance.py:2651} INFO - 0 downstream tasks scheduled from follow-on schedule check
