[2023-08-17T14:59:08.545-0600] {taskinstance.py:1103} INFO - Dependencies all met for dep_context=non-requeueable deps ti=<TaskInstance: Respaldar_Documentos_Electronicos.sincronizar_archivos scheduled__2023-08-16T08:00:00+00:00 [queued]>
[2023-08-17T14:59:08.558-0600] {taskinstance.py:1103} INFO - Dependencies all met for dep_context=requeueable deps ti=<TaskInstance: Respaldar_Documentos_Electronicos.sincronizar_archivos scheduled__2023-08-16T08:00:00+00:00 [queued]>
[2023-08-17T14:59:08.558-0600] {taskinstance.py:1308} INFO - Starting attempt 2 of 2
[2023-08-17T14:59:08.582-0600] {taskinstance.py:1327} INFO - Executing <Task(SSHOperator): sincronizar_archivos> on 2023-08-16 08:00:00+00:00
[2023-08-17T14:59:08.588-0600] {standard_task_runner.py:57} INFO - Started process 1413 to run task
[2023-08-17T14:59:08.593-0600] {standard_task_runner.py:84} INFO - Running: ['airflow', 'tasks', 'run', 'Respaldar_Documentos_Electronicos', 'sincronizar_archivos', 'scheduled__2023-08-16T08:00:00+00:00', '--job-id', '10', '--raw', '--subdir', 'DAGS_FOLDER/respaldar_documentos_electronicos.py', '--cfg-path', '/tmp/tmpup7wiwoc']
[2023-08-17T14:59:08.595-0600] {standard_task_runner.py:85} INFO - Job 10: Subtask sincronizar_archivos
[2023-08-17T14:59:08.661-0600] {task_command.py:410} INFO - Running <TaskInstance: Respaldar_Documentos_Electronicos.sincronizar_archivos scheduled__2023-08-16T08:00:00+00:00 [running]> on host f001d94713ae
[2023-08-17T14:59:08.792-0600] {taskinstance.py:1547} INFO - Exporting env vars: AIRFLOW_CTX_DAG_OWNER='airflow' AIRFLOW_CTX_DAG_ID='Respaldar_Documentos_Electronicos' AIRFLOW_CTX_TASK_ID='sincronizar_archivos' AIRFLOW_CTX_EXECUTION_DATE='2023-08-16T08:00:00+00:00' AIRFLOW_CTX_TRY_NUMBER='2' AIRFLOW_CTX_DAG_RUN_ID='scheduled__2023-08-16T08:00:00+00:00'
[2023-08-17T14:59:08.792-0600] {ssh.py:135} INFO - Creating ssh_client
[2023-08-17T14:59:08.842-0600] {ssh.py:112} INFO - ssh_hook is not provided or invalid. Trying ssh_conn_id to create SSHHook.
[2023-08-17T14:59:08.852-0600] {base.py:73} INFO - Using connection ID 'gabo_ssh' for task execution.
[2023-08-17T14:59:08.852-0600] {ssh.py:299} WARNING - No Host Key Verification. This won't protect against Man-In-The-Middle attacks
[2023-08-17T14:59:08.881-0600] {transport.py:1873} INFO - Connected (version 2.0, client OpenSSH_9.2p1)
[2023-08-17T14:59:09.081-0600] {transport.py:1873} INFO - Authentication (password) successful!
[2023-08-17T14:59:09.081-0600] {ssh.py:476} INFO - Running command: rsync -a /var/www/gabos/application/third_party/ ~/Dropbox/Inversiones_Garotas_Bonitas/GABO/respaldos/documentos_electronicos
[2023-08-17T14:59:09.219-0600] {ssh.py:527} WARNING - rsync: [Receiver] mkdir "/home/ambiente_admin/Dropbox/Inversiones_Garotas_Bonitas/GABO/respaldos/documentos_electronicos" failed: No such file or directory (2)
[2023-08-17T14:59:09.219-0600] {ssh.py:527} WARNING - rsync error: error in file IO (code 11) at main.c(791) [Receiver=3.2.7]
[2023-08-17T14:59:09.347-0600] {taskinstance.py:1824} ERROR - Task failed with exception
Traceback (most recent call last):
  File "/home/airflow/.local/lib/python3.7/site-packages/airflow/providers/ssh/operators/ssh.py", line 173, in execute
    result = self.run_ssh_client_command(ssh_client, self.command, context=context)
  File "/home/airflow/.local/lib/python3.7/site-packages/airflow/providers/ssh/operators/ssh.py", line 161, in run_ssh_client_command
    self.raise_for_status(exit_status, agg_stderr, context=context)
  File "/home/airflow/.local/lib/python3.7/site-packages/airflow/providers/ssh/operators/ssh.py", line 154, in raise_for_status
    raise AirflowException(f"SSH operator error: exit status = {exit_status}")
airflow.exceptions.AirflowException: SSH operator error: exit status = 11
[2023-08-17T14:59:09.353-0600] {taskinstance.py:1350} INFO - Marking task as FAILED. dag_id=Respaldar_Documentos_Electronicos, task_id=sincronizar_archivos, execution_date=20230816T080000, start_date=20230817T205908, end_date=20230817T205909
[2023-08-17T14:59:09.370-0600] {standard_task_runner.py:109} ERROR - Failed to execute job 10 for task sincronizar_archivos (SSH operator error: exit status = 11; 1413)
[2023-08-17T14:59:09.406-0600] {local_task_job_runner.py:225} INFO - Task exited with return code 1
[2023-08-17T14:59:09.436-0600] {taskinstance.py:2651} INFO - 0 downstream tasks scheduled from follow-on schedule check
